Workbook
Name UPDATE: 'Data Sheet'!$E$1

Sheet Financials>

Sheet HistoricalsFS
B2: ="Historical Financial Statement"&" - "&'Data Sheet'!B1 -> Historical Financial Statement - ASIAN PAINTS LTD
B3: Years | C3: 42460 | D3: 42825 | E3: 43190 | F3: 43555 | G3: 43921 | H3: 44286 | I3: 44651 | J3: 45016 | K3: 45382 | L3: 45747 | M3: LTM
A5: # | B5: Income Statement
B6: Sales | C6: =IFERROR('Data Sheet'!B17,0) -> 14271.49 | D6: =IFERROR('Data Sheet'!C17,0) -> 15061.99 | E6: =IFERROR('Data Sheet'!D17,0) -> 16824.55 | F6: =IFERROR('Data Sheet'!E17,0) -> 19240.13 | G6: =IFERROR('Data Sheet'!F17,0) -> 20211.25 | H6: =IFERROR('Data Sheet'!G17,0) -> 21712.79 | I6: =IFERROR('Data Sheet'!H17,0) -> 29101.28 | J6: =IFERROR('Data Sheet'!I17,0) -> 34488.59 | ... L6: =IFERROR('Data Sheet'!K17,0) -> 33905.62 | M6: =IFERROR(SUM('Data Sheet'!H42:K42),0) -> 34695.75
B7: Sales Growth | D7: =D6/C6-1 -> 0.055390152 | E7: =E6/D6-1 -> 0.11702039 | F7: =F6/E6-1 -> 0.14357472 | G7: =G6/F6-1 -> 0.050473671 | H7: =H6/G6-1 -> 0.074292288 | I7: =I6/H6-1 -> 0.34028285 | J7: =J6/I6-1 -> 0.18512278 | K7: =K6/J6-1 -> 0.029173127 | ... M7: =M6/L6-1 -> 0.023303806
B9: COGS | C9: =IFERROR(SUM('Data Sheet'!B18,'Data Sheet'!B20:B22)-1*'Data Sheet'!B19,0) -> 9413.84 | D9: =IFERROR(SUM('Data Sheet'!C18,'Data Sheet'!C20:C22)-1*'Data Sheet'!C19,0) -> 9732.66 | E9: =IFERROR(SUM('Data Sheet'!D18,'Data Sheet'!D20:D22)-1*'Data Sheet'!D19,0) -> 11194.17 | F9: =IFERROR(SUM('Data Sheet'!E18,'Data Sheet'!E20:E22)-1*'Data Sheet'!E19,0) -> 12905.81 | G9: =IFERROR(SUM('Data Sheet'!F18,'Data Sheet'!F20:F22)-1*'Data Sheet'!F19,0) -> 13158.02 | H9: =IFERROR(SUM('Data Sheet'!G18,'Data Sheet'!G20:G22)-1*'Data Sheet'!G19,0) -> 14035.07 | I9: =IFERROR(SUM('Data Sheet'!H18,'Data Sheet'!H20:H22)-1*'Data Sheet'!H19,0) -> 20590.57 | J9: =IFERROR(SUM('Data Sheet'!I18,'Data Sheet'!I20:I22)-1*'Data Sheet'!I19,0) -> 23766.7 | ... L9: =IFERROR(SUM('Data Sheet'!K18,'Data Sheet'!K20:K22)-1*'Data Sheet'!K19,0) -> 22741.27 | M9: =SUM('Data Sheet'!H43:K43) -> 28350.24
B10: COGS % Sales | C10: =C9/C6 -> 0.65962559 | D10: =D9/D6 -> 0.64617358 | E10: =E9/E6 -> 0.66534736 | F10: =F9/F6 -> 0.67077561 | G10: =G9/G6 -> 0.65102455 | H10: =H9/H6 -> 0.64639643 | I10: =I9/I6 -> 0.7075486 | J10: =J9/J6 -> 0.68911776 | ... M10: =M9/M6 -> 0.81710988
B12: Gross Profit | C12: =C6-C9 -> 4857.65 | D12: =D6-D9 -> 5329.33 | E12: =E6-E9 -> 5630.38 | F12: =F6-F9 -> 6334.32 | G12: =G6-G9 -> 7053.23 | H12: =H6-H9 -> 7677.72 | I12: =I6-I9 -> 8510.71 | J12: =J6-J9 -> 10721.89 | ... M12: =M6-M9 -> 6345.51
B13: Gross margin | C13: =C12/C6 -> 0.34037441 | D13: =D12/D6 -> 0.35382642 | E13: =E12/E6 -> 0.33465264 | F13: =F12/F6 -> 0.32922439 | G13: =G12/G6 -> 0.34897545 | H13: =H12/H6 -> 0.35360357 | I13: =I12/I6 -> 0.2924514 | J13: =J12/J6 -> 0.31088224 | ... M13: =M12/M6 -> 0.18289012
B15: Selling & General Expenses | C15: =IFERROR(SUM('Data Sheet'!B23:B24),0) -> 2132.61 | D15: =IFERROR(SUM('Data Sheet'!C23:C24),0) -> 2335.57 | E15: =IFERROR(SUM('Data Sheet'!D23:D24),0) -> 2426.37 | F15: =IFERROR(SUM('Data Sheet'!E23:E24),0) -> 2569.38 | G15: =IFERROR(SUM('Data Sheet'!F23:F24),0) -> 2891.46 | H15: =IFERROR(SUM('Data Sheet'!G23:G24),0) -> 2822.12 | I15: =IFERROR(SUM('Data Sheet'!H23:H24),0) -> 3707.1 | J15: =IFERROR(SUM('Data Sheet'!I23:I24),0) -> 4462.05 | ... L15: =IFERROR(SUM('Data Sheet'!K23:K24),0) -> 5158.14 | M15: 0
B16: S&G Exp% Sales | C16: =C15/C6 -> 0.14943149 | D16: =D15/D6 -> 0.15506384 | E16: =E15/E6 -> 0.14421604 | F16: =F15/F6 -> 0.13354276 | G16: =G15/G6 -> 0.14306191 | H16: =H15/H6 -> 0.12997501 | I16: =I15/I6 -> 0.12738615 | J16: =J15/J6 -> 0.12937757 | ... M16: =M15/M6 -> 0
B18: EBITDA | C18: =C12-C15 -> 2725.04 | D18: =D12-D15 -> 2993.76 | E18: =E12-E15 -> 3204.01 | F18: =F12-F15 -> 3764.94 | G18: =G12-G15 -> 4161.77 | H18: =H12-H15 -> 4855.6 | I18: =I12-I15 -> 4803.61 | J18: =J12-J15 -> 6259.84 | ... M18: =M12-M15 -> 6345.51
B19: Ebitda Margin | C19: =C18/C6 -> 0.19094292 | D19: =D18/D6 -> 0.19876258 | E19: =E18/E6 -> 0.19043659 | F19: =F18/F6 -> 0.19568163 | G19: =G18/G6 -> 0.20591354 | H19: =H18/H6 -> 0.22362856 | I19: =I18/I6 -> 0.16506525 | J19: =J18/J6 -> 0.18150467 | ... M19: =M18/M6 -> 0.18289012
B21: Interest | C21: =IFERROR('Data Sheet'!B27,0) -> 49 | D21: =IFERROR('Data Sheet'!C27,0) -> 37.33 | E21: =IFERROR('Data Sheet'!D27,0) -> 41.47 | F21: =IFERROR('Data Sheet'!E27,0) -> 110.47 | G21: =IFERROR('Data Sheet'!F27,0) -> 102.33 | H21: =IFERROR('Data Sheet'!G27,0) -> 91.63 | I21: =IFERROR('Data Sheet'!H27,0) -> 95.41 | J21: =IFERROR('Data Sheet'!I27,0) -> 144.45 | ... L21: =IFERROR('Data Sheet'!K27,0) -> 227.02 | M21: =SUM('Data Sheet'!H46:K46) -> 189.1
B22: Interest & Sales | C22: =C21/C6 -> 0.0034334187 | D22: =D21/D6 -> 0.0024784242 | E22: =E21/E6 -> 0.0024648505 | F22: =F21/F6 -> 0.0057416452 | G22: =G21/G6 -> 0.0050630218 | H22: =H21/H6 -> 0.0042200933 | I22: =I21/I6 -> 0.0032785499 | J22: =J21/J6 -> 0.0041883417 | ... M22: =M21/M6 -> 0.0054502353
B24: Depriciation | C24: =IFERROR('Data Sheet'!B26,0) -> 275.58 | D24: =IFERROR('Data Sheet'!C26,0) -> 334.79 | E24: =IFERROR('Data Sheet'!D26,0) -> 360.47 | F24: =IFERROR('Data Sheet'!E26,0) -> 622.14 | G24: =IFERROR('Data Sheet'!F26,0) -> 780.5 | H24: =IFERROR('Data Sheet'!G26,0) -> 791.27 | I24: =IFERROR('Data Sheet'!H26,0) -> 816.36 | J24: =IFERROR('Data Sheet'!I26,0) -> 858.02 | ... L24: =IFERROR('Data Sheet'!K26,0) -> 1026.34 | M24: =SUM('Data Sheet'!H45:K45) -> 1219.97
B25: Depriciation % Sales | C25: =C24/C6 -> 0.019309827 | D25: =D24/D6 -> 0.022227475 | E25: =E24/E6 -> 0.021425239 | F25: =F24/F6 -> 0.03233554 | G25: =G24/G6 -> 0.038617107 | H25: =H24/H6 -> 0.036442576 | I25: =I24/I6 -> 0.028052374 | J25: =J24/J6 -> 0.024878373 | ... M25: =M24/M6 -> 0.035161943
B27: Earnings Before Tax | C27: =C18-SUM(C21,C24) -> 2400.46 | D27: =D18-SUM(D21,D24) -> 2621.64 | E27: =E18-SUM(E21,E24) -> 2802.07 | F27: =F18-SUM(F21,F24) -> 3032.33 | G27: =G18-SUM(G21,G24) -> 3278.94 | H27: =H18-SUM(H21,H24) -> 3972.7 | I27: =I18-SUM(I21,I24) -> 3891.84 | J27: =J18-SUM(J21,J24) -> 5257.37 | ... M27: =M18-SUM(M21,M24) -> 4936.44
B28: Ebt % Sales | C28: =C27/C6 -> 0.16819968 | D28: =D27/D6 -> 0.17405668 | E28: =E27/E6 -> 0.1665465 | F28: =F27/F6 -> 0.15760444 | G28: =G27/G6 -> 0.16223341 | H28: =H27/H6 -> 0.18296589 | I28: =I27/I6 -> 0.13373432 | J28: =J27/J6 -> 0.15243795 | ... M28: =M27/M6 -> 0.14227794
B30: Tax | C30: =IFERROR('Data Sheet'!B48,0) -> 418.55 | D30: =IFERROR('Data Sheet'!C48,0) -> 492.62 | E30: =IFERROR('Data Sheet'!D48,0) -> 348.79 | F30: =IFERROR('Data Sheet'!E48,0) -> 416.83 | G30: =IFERROR('Data Sheet'!F48,0) -> 265.38 | H30: =IFERROR('Data Sheet'!G48,0) -> 389.73 | I30: =IFERROR('Data Sheet'!H48,0) -> 321.42 | J30: =IFERROR('Data Sheet'!I48,0) -> 391.66 | ... L30: =IFERROR('Data Sheet'!K48,0) -> 415.17 | M30: =SUM('Data Sheet'!H48:K48) -> 1501.54
B31: Effective Tax Rate | C31: =C30/C27 -> 0.17436241 | D31: =D30/D27 -> 0.18790528 | E31: =E30/E27 -> 0.12447583 | F31: =F30/F27 -> 0.13746195 | G31: =G30/G27 -> 0.080934692 | H31: =H30/H27 -> 0.098102046 | I31: =I30/I27 -> 0.082588185 | J31: =J30/J27 -> 0.074497325 | ... M31: =M30/M27 -> 0.30417467
B33: Net Profit | C33: =C27-C30 -> 1981.91 | D33: =D27-D30 -> 2129.02 | E33: =E27-E30 -> 2453.28 | F33: =F27-F30 -> 2615.5 | G33: =G27-G30 -> 3013.56 | H33: =H27-H30 -> 3582.97 | I33: =I27-I30 -> 3570.42 | J33: =J27-J30 -> 4865.71 | ... M33: =M27-M30 -> 3434.9
B34: Net Margins | C34: =C33/C6 -> 0.13887197 | D34: =D33/D6 -> 0.14135051 | E34: =E33/E6 -> 0.14581549 | F34: =F33/F6 -> 0.13593983 | G34: =G33/G6 -> 0.1491031 | H34: =H33/H6 -> 0.16501656 | I34: =I33/I6 -> 0.12268945 | J34: =J33/J6 -> 0.14108173 | ... M34: =M33/M6 -> 0.099000598
B36: No. of Equity Shares | C36: =IFERROR('Data Sheet'!B93,0) -> 95.92 | D36: =IFERROR('Data Sheet'!C93,0) -> 95.92 | E36: =IFERROR('Data Sheet'!D93,0) -> 95.92 | F36: =IFERROR('Data Sheet'!E93,0) -> 95.92 | G36: =IFERROR('Data Sheet'!F93,0) -> 95.92 | H36: =IFERROR('Data Sheet'!G93,0) -> 95.92 | I36: =IFERROR('Data Sheet'!H93,0) -> 95.92 | J36: =IFERROR('Data Sheet'!I93,0) -> 95.92 | ... L36: =IFERROR('Data Sheet'!K93,0) -> 95.92 | M36: 0
B38: Earning Per Share | C38: =C33/C36 -> 20.662114 | D38: =D33/D36 -> 22.195788 | E38: =E33/E36 -> 25.576314 | F38: =F33/F36 -> 27.267515 | G38: =G33/G36 -> 31.417431 | H38: =H33/H36 -> 37.353732 | I38: =I33/I36 -> 37.222894 | J38: =J33/J36 -> 50.726751 | ... L38: =L33/L36 -> 45.221852 | M38: 0
B39: Eps Growth% | D39: =D38/C38-1 -> 0.074226378 | E39: =E38/D38-1 -> 0.15230482 | F39: =F38/E38-1 -> 0.06612372 | G39: =G38/F38-1 -> 0.1521927 | H39: =H38/G38-1 -> 0.18894928 | I39: =I38/H38-1 -> -0.0035026807 | J39: =J38/I38-1 -> 0.36278365 | K39: =K38/J38-1 -> 0.26467052 | ... M39: =M38/L38-1 -> -1
B41: Dividend Per Share | C41: =IFERROR('Data Sheet'!B31,0) -> 719.4 | D41: =IFERROR('Data Sheet'!C31,0) -> 987.98 | E41: =IFERROR('Data Sheet'!D31,0) -> 834.5 | F41: =IFERROR('Data Sheet'!E31,0) -> 1007.16 | G41: =IFERROR('Data Sheet'!F31,0) -> 1151.04 | H41: =IFERROR('Data Sheet'!G31,0) -> 1712.17 | I41: =IFERROR('Data Sheet'!H31,0) -> 1836.87 | J41: =IFERROR('Data Sheet'!I31,0) -> 2460.35 | ... L41: =IFERROR('Data Sheet'!K31,0) -> 2378.82 | M41: 0
B42: Dividend Payout Ratio | C42: =C41/C38 -> 34.817347 | D42: =D41/D38 -> 44.512049 | E42: =E41/E38 -> 32.627845 | F42: =F41/F38 -> 36.93626 | G42: =G41/G38 -> 36.636986 | H42: =H41/H38 -> 45.836651 | I42: =I41/I38 -> 49.347856 | J42: =J41/J38 -> 48.502022 | ... L42: =L41/L38 -> 52.60333 | M42: 0
B44: Retained Earnings | C44: =IFERROR(IF(C38>C41,1-C42,0),0) -> 0 | D44: =IFERROR(IF(D38>D41,1-D42,0),0) -> 0 | E44: =IFERROR(IF(E38>E41,1-E42,0),0) -> 0 | F44: =IFERROR(IF(F38>F41,1-F42,0),0) -> 0 | G44: =IFERROR(IF(G38>G41,1-G42,0),0) -> 0 | H44: =IFERROR(IF(H38>H41,1-H42,0),0) -> 0 | I44: =IFERROR(IF(I38>I41,1-I42,0),0) -> 0 | J44: =IFERROR(IF(J38>J41,1-J42,0),0) -> 0 | ... M44: =IFERROR(IF(M38>M41,1-M42,0),0) -> 0
A46: # | B46: Balance Sheet
B47: Report Date | C47: 42460 | D47: 42825 | E47: 43190 | F47: 43555 | G47: 43921 | H47: 44286 | I47: 44651 | J47: 45016 | K47: 45382 | L47: 45747
B48: Equity Share Capital | C48: =IFERROR('Data Sheet'!B57,0) -> 95.92 | D48: =IFERROR('Data Sheet'!C57,0) -> 95.92 | E48: =IFERROR('Data Sheet'!D57,0) -> 95.92 | F48: =IFERROR('Data Sheet'!E57,0) -> 95.92 | G48: =IFERROR('Data Sheet'!F57,0) -> 95.92 | H48: =IFERROR('Data Sheet'!G57,0) -> 95.92 | I48: =IFERROR('Data Sheet'!H57,0) -> 95.92 | J48: =IFERROR('Data Sheet'!I57,0) -> 95.92 | ... L48: =IFERROR('Data Sheet'!K57,0) -> 95.92
B49: Reserves | C49: =IFERROR('Data Sheet'!B58,0) -> 6428.9 | D49: =IFERROR('Data Sheet'!C58,0) -> 7507.97 | E49: =IFERROR('Data Sheet'!D58,0) -> 8314.31 | F49: =IFERROR('Data Sheet'!E58,0) -> 9374.63 | G49: =IFERROR('Data Sheet'!F58,0) -> 10034.24 | H49: =IFERROR('Data Sheet'!G58,0) -> 12710.37 | I49: =IFERROR('Data Sheet'!H58,0) -> 13715.64 | J49: =IFERROR('Data Sheet'!I58,0) -> 15896.31 | ... L49: =IFERROR('Data Sheet'!K58,0) -> 19303.89
B50: Borrowings | C50: =IFERROR('Data Sheet'!B59,0) -> 323.29 | D50: =IFERROR('Data Sheet'!C59,0) -> 560.34 | E50: =IFERROR('Data Sheet'!D59,0) -> 533.43 | F50: =IFERROR('Data Sheet'!E59,0) -> 1319.6 | G50: =IFERROR('Data Sheet'!F59,0) -> 1118.5 | H50: =IFERROR('Data Sheet'!G59,0) -> 1093.12 | I50: =IFERROR('Data Sheet'!H59,0) -> 1586.88 | J50: =IFERROR('Data Sheet'!I59,0) -> 1932.62 | ... L50: =IFERROR('Data Sheet'!K59,0) -> 2290.29
B51: Other Liabilities | C51: =IFERROR('Data Sheet'!B60,0) -> 3710.92 | D51: =IFERROR('Data Sheet'!C60,0) -> 4240.96 | E51: =IFERROR('Data Sheet'!D60,0) -> 4819.82 | F51: =IFERROR('Data Sheet'!E60,0) -> 5458.69 | G51: =IFERROR('Data Sheet'!F60,0) -> 4889.31 | H51: =IFERROR('Data Sheet'!G60,0) -> 6455.93 | I51: =IFERROR('Data Sheet'!H60,0) -> 7559.99 | J51: =IFERROR('Data Sheet'!I60,0) -> 7854.48 | ... L51: =IFERROR('Data Sheet'!K60,0) -> 8665.15
B52: Total Liabilities | C52: =SUM(C48:C51) -> 10559.03 | D52: =SUM(D48:D51) -> 12405.19 | E52: =SUM(E48:E51) -> 13763.48 | F52: =SUM(F48:F51) -> 16248.84 | G52: =SUM(G48:G51) -> 16137.97 | H52: =SUM(H48:H51) -> 20355.34 | I52: =SUM(I48:I51) -> 22958.43 | J52: =SUM(J48:J51) -> 25779.33 | ... L52: =SUM(L48:L51) -> 30355.25
B54: Fixed Assets Net Block | C54: =IFERROR('Data Sheet'!B62,0) -> 3416.35 | D54: =IFERROR('Data Sheet'!C62,0) -> 3303.74 | E54: =IFERROR('Data Sheet'!D62,0) -> 3732.24 | F54: =IFERROR('Data Sheet'!E62,0) -> 6496.56 | G54: =IFERROR('Data Sheet'!F62,0) -> 6272.31 | H54: =IFERROR('Data Sheet'!G62,0) -> 5858.52 | I54: =IFERROR('Data Sheet'!H62,0) -> 5519.06 | J54: =IFERROR('Data Sheet'!I62,0) -> 5770.46 | ... L54: =IFERROR('Data Sheet'!K62,0) -> 9220.1
B55: Capital Work in Progress | C55: =IFERROR('Data Sheet'!B63,0) -> 106.59 | D55: =IFERROR('Data Sheet'!C63,0) -> 257.54 | E55: =IFERROR('Data Sheet'!D63,0) -> 1405.11 | F55: =IFERROR('Data Sheet'!E63,0) -> 209.67 | G55: =IFERROR('Data Sheet'!F63,0) -> 140.24 | H55: =IFERROR('Data Sheet'!G63,0) -> 182.98 | I55: =IFERROR('Data Sheet'!H63,0) -> 426.43 | J55: =IFERROR('Data Sheet'!I63,0) -> 1019.59 | ... L55: =IFERROR('Data Sheet'!K63,0) -> 1254.49
B56: Investments | C56: =IFERROR('Data Sheet'!B64,0) -> 2712.13 | D56: =IFERROR('Data Sheet'!C64,0) -> 2651.99 | E56: =IFERROR('Data Sheet'!D64,0) -> 2140.7 | F56: =IFERROR('Data Sheet'!E64,0) -> 2568.58 | G56: =IFERROR('Data Sheet'!F64,0) -> 2018.85 | H56: =IFERROR('Data Sheet'!G64,0) -> 4736.8 | I56: =IFERROR('Data Sheet'!H64,0) -> 3247.53 | J56: =IFERROR('Data Sheet'!I64,0) -> 4261.71 | ... L56: =IFERROR('Data Sheet'!K64,0) -> 4724.75
B57: Other Assets | C57: =IFERROR('Data Sheet'!B65-SUM('Data Sheet'!B67:B69),0) -> 714.68 | D57: =IFERROR('Data Sheet'!C65-SUM('Data Sheet'!C67:C69),0) -> 1317.17 | E57: =IFERROR('Data Sheet'!D65-SUM('Data Sheet'!D67:D69),0) -> 1691.84 | F57: =IFERROR('Data Sheet'!E65-SUM('Data Sheet'!E67:E69),0) -> 1471.96 | G57: =IFERROR('Data Sheet'!F65-SUM('Data Sheet'!F67:F69),0) -> 1738.71 | H57: =IFERROR('Data Sheet'!G65-SUM('Data Sheet'!G67:G69),0) -> 2565.52 | I57: =IFERROR('Data Sheet'!H65-SUM('Data Sheet'!H67:H69),0) -> 2876.66 | J57: =IFERROR('Data Sheet'!I65-SUM('Data Sheet'!I67:I69),0) -> 3036.17 | ... L57: =IFERROR('Data Sheet'!K65-SUM('Data Sheet'!K67:K69),0) -> 3341.01
...

Sheet Basic Forecasting
B2: ='Data Sheet'!B1&" - "&"Sales Forecasting" -> ASIAN PAINTS LTD - Sales Forecasting | G2: ='Data Sheet'!B1&" - "&"Ebitda Forecasting" -> ASIAN PAINTS LTD - Ebitda Forecasting
B3: Year Weight | C3: Year | D3: Sales | E3: Sales Growth | G3: Year Weight | H3: Year | I3: Ebitda | J3: Sales Growth
B4: 1 | C4: =HistoricalsFS!C3 -> 42460 | D4: {=TRANSPOSE(HistoricalsFS!C6:L6)} -> 14271.49 | G4: 1 | H4: =HistoricalsFS!C3 -> 42460 | I4: {=TRANSPOSE(HistoricalsFS!C18:L18)} -> 2725.04
B5: 2 | C5: =C4+365 -> 42825 | D5: 15061.99 | E5: =D5/D4-1 -> 0.055390152 | G5: 2 | H5: =H4+365 -> 42825 | I5: 2993.76 | J5: =I5/I4-1 -> 0.098611397 | L5: Arithmetic Growth of Sales | M5: Arithmetic Growth of Ebitda
B6: 3 | C6: =C5+365 -> 43190 | D6: 16824.55 | E6: =D6/D5-1 -> 0.11702039 | G6: 3 | H6: =H5+365 -> 43190 | I6: 3204.01 | J6: =I6/I5-1 -> 0.070229411 | L6: =AVERAGE(E5:E13) -> 0.10561774 | M6: =AVERAGE(J5:J13) -> 0.1013355
B7: 4 | C7: =C6+365 -> 43555 | D7: 19240.13 | E7: =D7/D6-1 -> 0.14357472 | G7: 4 | H7: =H6+365 -> 43555 | I7: 3764.94 | J7: =I7/I6-1 -> 0.17507124
B8: 5 | C8: =C7+365 -> 43920 | D8: 20211.25 | E8: =D8/D7-1 -> 0.050473671 | G8: 5 | H8: =H7+365 -> 43920 | I8: 4161.77 | J8: =I8/I7-1 -> 0.10540141 | L8: Geometric Growth of Sales | M8: Geometric Growth of Ebitda
B9: 6 | C9: =C8+365 -> 44285 | D9: 21712.79 | E9: =D9/D8-1 -> 0.074292288 | G9: 6 | H9: =H8+365 -> 44285 | I9: 4855.6 | J9: =I9/I8-1 -> 0.16671512 | L9: =_xlfn.RRI($B$13,D4,D13) -> 0.090385926 | M9: =_xlfn.RRI(G13,I4,I13) -> 0.08223796
B10: 7 | C10: =C9+365 -> 44650 | D10: 29101.28 | E10: =D10/D9-1 -> 0.34028285 | G10: 7 | H10: =H9+365 -> 44650 | I10: 4803.61 | J10: =I10/I9-1 -> -0.010707225
B11: 8 | C11: =C10+365 -> 45015 | D11: 34488.59 | E11: =D11/D10-1 -> 0.18512278 | G11: 8 | H11: =H10+365 -> 45015 | I11: 6259.84 | J11: =I11/I10-1 -> 0.30315325 | L11: Standard Deviation of Sales | M11: Standard Deviation of Ebitda
B12: 9 | C12: =C11+365 -> 45380 | D12: 35494.73 | E12: =D12/D11-1 -> 0.029173127 | G12: 9 | H12: =H11+365 -> 45380 | I12: 7584.98 | J12: =I12/I11-1 -> 0.21168912 | L12: =_xlfn.STDEV.S(E4:E13) -> 0.11065985 | M12: =_xlfn.STDEV.S(J4:J13) -> 0.14660432
B13: 10 | C13: =C12+365 -> 45745 | D13: 33905.62 | E13: =D13/D12-1 -> -0.044770308 | G13: 10 | H13: =H12+365 -> 45745 | I13: 6006.21 | J13: =I13/I12-1 -> -0.20814425
B14: 11 | C14: =C13+365 -> 46110 | D14: =FORECAST(B14,$D$4:$D$13,$B$4:$B$13) -> 38669.293 | E14: =D14/D13-1 -> 0.14049805 | G14: 11 | H14: =H13+365 -> 46110 | I14: =FORECAST(G14,$I$4:$I$13,$G$4:$G$13) -> 7327.9113 | J14: =I14/I13-1 -> 0.2200558
B15: 12 | C15: =C14+365 -> 46475 | D15: =FORECAST(B15,$D$4:$D$13,$B$4:$B$13) -> 41330.757 | E15: =D15/D14-1 -> 0.068826287 | G15: 12 | H15: =H14+365 -> 46475 | I15: =FORECAST(G15,$I$4:$I$13,$G$4:$G$13) -> 7817.3541 | J15: =I15/I14-1 -> 0.066791582
B16: 13 | C16: =C15+365 -> 46840 | D16: =FORECAST(B16,$D$4:$D$13,$B$4:$B$13) -> 43992.221 | E16: =D16/D15-1 -> 0.064394269 | G16: 13 | H16: =H15+365 -> 46840 | I16: =FORECAST(G16,$I$4:$I$13,$G$4:$G$13) -> 8306.7969 | J16: =I16/I15-1 -> 0.062609776
B17: 14 | C17: =C16+365 -> 47205 | D17: =FORECAST(B17,$D$4:$D$13,$B$4:$B$13) -> 46653.685 | E17: =D17/D16-1 -> 0.060498511 | G17: 14 | H17: =H16+365 -> 47205 | I17: =FORECAST(G17,$I$4:$I$13,$G$4:$G$13) -> 8796.2397 | J17: =I17/I16-1 -> 0.05892076
B18: 15 | C18: =C17+365 -> 47570 | D18: =FORECAST(B18,$D$4:$D$13,$B$4:$B$13) -> 49315.149 | E18: =D18/D17-1 -> 0.057047238 | G18: 15 | H18: =H17+365 -> 47570 | I18: =FORECAST(G18,$I$4:$I$13,$G$4:$G$13) -> 9285.6825 | J18: =I18/I17-1 -> 0.055642275
B19: 16 | C19: =C18+365 -> 47935 | D19: =FORECAST(B19,$D$4:$D$13,$B$4:$B$13) -> 51976.613 | E19: =D19/D18-1 -> 0.053968485 | G19: 16 | H19: =H18+365 -> 47935 | I19: =FORECAST(G19,$I$4:$I$13,$G$4:$G$13) -> 9775.1253 | J19: =I19/I18-1 -> 0.052709404
B20: 17 | C20: =C19+365 -> 48300 | D20: =FORECAST(B20,$D$4:$D$13,$B$4:$B$13) -> 54638.077 | E20: =D20/D19-1 -> 0.051205027 | G20: 17 | H20: =H19+365 -> 48300 | I20: =FORECAST(G20,$I$4:$I$13,$G$4:$G$13) -> 10264.568 | J20: =I20/I19-1 -> 0.050070232
B21: 18 | C21: =C20+365 -> 48665 | D21: =FORECAST(B21,$D$4:$D$13,$B$4:$B$13) -> 57299.54 | E21: =D21/D20-1 -> 0.04871079 | G21: 18 | H21: =H20+365 -> 48665 | I21: =FORECAST(G21,$I$4:$I$13,$G$4:$G$13) -> 10754.011 | J21: =I21/I20-1 -> 0.047682746
B22: 19 | C22: =C21+365 -> 49030 | D22: =FORECAST(B22,$D$4:$D$13,$B$4:$B$13) -> 59961.004 | E22: =D22/D21-1 -> 0.046448259 | G22: 19 | H22: =H21+365 -> 49030 | I22: =FORECAST(G22,$I$4:$I$13,$G$4:$G$13) -> 11243.454 | J22: =I22/I21-1 -> 0.045512581

Sheet Ratio Analysis
B2: ="Ratio Analysis"&" - "&#REF! -> #REF!
B3: Years | C3: 42460 | D3: 42825 | E3: 43190 | F3: 43555 | G3: 43921 | H3: 44286 | I3: 44651 | J3: 45016 | K3: 45382 | L3: 45747 | M3: Trend | N3: Mean | O3: Median
B5: Sales Growth | D5: =IFERROR(HistoricalsFS!D7,0) -> 0.055390152 | E5: =IFERROR(HistoricalsFS!E7,0) -> 0.11702039 | F5: =IFERROR(HistoricalsFS!F7,0) -> 0.14357472 | G5: =IFERROR(HistoricalsFS!G7,0) -> 0.050473671 | H5: =IFERROR(HistoricalsFS!H7,0) -> 0.074292288 | I5: =IFERROR(HistoricalsFS!I7,0) -> 0.34028285 | J5: =IFERROR(HistoricalsFS!J7,0) -> 0.18512278 | K5: =IFERROR(HistoricalsFS!K7,0) -> 0.029173127 | L5: =IFERROR(HistoricalsFS!L7,0) -> -0.044770308 | N5: =AVERAGE(D5:L5) -> 0.10561774 | O5: =MEDIAN(D5:L5) -> 0.074292288
B6: EBITDA Growth | D6: =IFERROR(HistoricalsFS!D18/HistoricalsFS!C18-1,0) -> 0.098611397 | E6: =IFERROR(HistoricalsFS!E18/HistoricalsFS!D18-1,0) -> 0.070229411 | F6: =IFERROR(HistoricalsFS!F18/HistoricalsFS!E18-1,0) -> 0.17507124 | G6: =IFERROR(HistoricalsFS!G18/HistoricalsFS!F18-1,0) -> 0.10540141 | H6: =IFERROR(HistoricalsFS!H18/HistoricalsFS!G18-1,0) -> 0.16671512 | I6: =IFERROR(HistoricalsFS!I18/HistoricalsFS!H18-1,0) -> -0.010707225 | J6: =IFERROR(HistoricalsFS!J18/HistoricalsFS!I18-1,0) -> 0.30315325 | K6: =IFERROR(HistoricalsFS!K18/HistoricalsFS!J18-1,0) -> 0.21168912 | L6: =IFERROR(HistoricalsFS!L18/HistoricalsFS!K18-1,0) -> -0.20814425 | N6: =AVERAGE(D6:L6) -> 0.1013355 | O6: =MEDIAN(D6:L6) -> 0.10540141
B7: EBIT Growth | D7: =IFERROR((HistoricalsFS!D18-HistoricalsFS!D24)/(HistoricalsFS!C18-HistoricalsFS!C24)-1,0) -> 0.085533138 | E7: =IFERROR((HistoricalsFS!E18-HistoricalsFS!E24)/(HistoricalsFS!D18-HistoricalsFS!D24)-1,0) -> 0.069414096 | F7: =IFERROR((HistoricalsFS!F18-HistoricalsFS!F24)/(HistoricalsFS!E18-HistoricalsFS!E24)-1,0) -> 0.10524206 | G7: =IFERROR((HistoricalsFS!G18-HistoricalsFS!G24)/(HistoricalsFS!F18-HistoricalsFS!F24)-1,0) -> 0.075878198 | H7: =IFERROR((HistoricalsFS!H18-HistoricalsFS!H24)/(HistoricalsFS!G18-HistoricalsFS!G24)-1,0) -> 0.20201285 | I7: =IFERROR((HistoricalsFS!I18-HistoricalsFS!I24)/(HistoricalsFS!H18-HistoricalsFS!H24)-1,0) -> -0.018964995 | J7: =IFERROR((HistoricalsFS!J18-HistoricalsFS!J24)/(HistoricalsFS!I18-HistoricalsFS!I24)-1,0) -> 0.35477334 | K7: =IFERROR((HistoricalsFS!K18-HistoricalsFS!K24)/(HistoricalsFS!J18-HistoricalsFS!J24)-1,0) -> 0.24624293 | L7: =IFERROR((HistoricalsFS!L18-HistoricalsFS!L24)/(HistoricalsFS!K18-HistoricalsFS!K24)-1,0) -> -0.26026667 | N7: =AVERAGE(D7:L7) -> 0.09554055 | O7: =MEDIAN(D7:L7) -> 0.085533138
B8: Net Profit Growth | D8: =IFERROR(HistoricalsFS!D33/HistoricalsFS!C33-1,0) -> 0.074226378 | E8: =IFERROR(HistoricalsFS!E33/HistoricalsFS!D33-1,0) -> 0.15230482 | F8: =IFERROR(HistoricalsFS!F33/HistoricalsFS!E33-1,0) -> 0.06612372 | G8: =IFERROR(HistoricalsFS!G33/HistoricalsFS!F33-1,0) -> 0.1521927 | H8: =IFERROR(HistoricalsFS!H33/HistoricalsFS!G33-1,0) -> 0.18894928 | I8: =IFERROR(HistoricalsFS!I33/HistoricalsFS!H33-1,0) -> -0.0035026807 | J8: =IFERROR(HistoricalsFS!J33/HistoricalsFS!I33-1,0) -> 0.36278365 | K8: =IFERROR(HistoricalsFS!K33/HistoricalsFS!J33-1,0) -> 0.26467052 | L8: =IFERROR(HistoricalsFS!L33/HistoricalsFS!K33-1,0) -> -0.29508964 | N8: =AVERAGE(D8:L8) -> 0.10696208 | O8: =MEDIAN(D8:L8) -> 0.1521927
B9: Dividend Growth | D9: =IFERROR(HistoricalsFS!D41/HistoricalsFS!C41-1,0) -> 0.37333889 | E9: =IFERROR(HistoricalsFS!E41/HistoricalsFS!D41-1,0) -> -0.15534727 | F9: =IFERROR(HistoricalsFS!F41/HistoricalsFS!E41-1,0) -> 0.20690234 | G9: =IFERROR(HistoricalsFS!G41/HistoricalsFS!F41-1,0) -> 0.14285714 | H9: =IFERROR(HistoricalsFS!H41/HistoricalsFS!G41-1,0) -> 0.48749826 | I9: =IFERROR(HistoricalsFS!I41/HistoricalsFS!H41-1,0) -> 0.072831553 | J9: =IFERROR(HistoricalsFS!J41/HistoricalsFS!I41-1,0) -> 0.33942522 | K9: =IFERROR(HistoricalsFS!K41/HistoricalsFS!J41-1,0) -> 0.29824618 | L9: =IFERROR(HistoricalsFS!L41/HistoricalsFS!K41-1,0) -> -0.25525494 | N9: =AVERAGE(D9:L9) -> 0.16783304 | O9: =MEDIAN(D9:L9) -> 0.20690234
B11: Gross Margin | C11: =IFERROR(HistoricalsFS!C13,0) -> 0.34037441 | D11: =IFERROR(HistoricalsFS!D13,0) -> 0.35382642 | E11: =IFERROR(HistoricalsFS!E13,0) -> 0.33465264 | F11: =IFERROR(HistoricalsFS!F13,0) -> 0.32922439 | G11: =IFERROR(HistoricalsFS!G13,0) -> 0.34897545 | H11: =IFERROR(HistoricalsFS!H13,0) -> 0.35360357 | I11: =IFERROR(HistoricalsFS!I13,0) -> 0.2924514 | J11: =IFERROR(HistoricalsFS!J13,0) -> 0.31088224 | ... L11: =IFERROR(HistoricalsFS!L13,0) -> 0.32927727 | N11: =AVERAGE(C11:L11) -> 0.33450028 | O11: =MEDIAN(C11:L11) -> 0.33751352
B12: Ebitda Margin | C12: =IFERROR(HistoricalsFS!C19,0) -> 0.19094292 | D12: =IFERROR(HistoricalsFS!D19,0) -> 0.19876258 | E12: =IFERROR(HistoricalsFS!E19,0) -> 0.19043659 | F12: =IFERROR(HistoricalsFS!F19,0) -> 0.19568163 | G12: =IFERROR(HistoricalsFS!G19,0) -> 0.20591354 | H12: =IFERROR(HistoricalsFS!H19,0) -> 0.22362856 | I12: =IFERROR(HistoricalsFS!I19,0) -> 0.16506525 | J12: =IFERROR(HistoricalsFS!J19,0) -> 0.18150467 | ... L12: =IFERROR(HistoricalsFS!L19,0) -> 0.17714497 | N12: =AVERAGE(C12:L12) -> 0.19427738 | O12: =MEDIAN(C12:L12) -> 0.19331228
B13: Ebit Margin | C13: =IFERROR((HistoricalsFS!C18-HistoricalsFS!C24)/HistoricalsFS!C6,0) -> 0.1716331 | D13: =IFERROR((HistoricalsFS!D18-HistoricalsFS!D24)/HistoricalsFS!D6,0) -> 0.17653511 | E13: =IFERROR((HistoricalsFS!E18-HistoricalsFS!E24)/HistoricalsFS!E6,0) -> 0.16901136 | F13: =IFERROR((HistoricalsFS!F18-HistoricalsFS!F24)/HistoricalsFS!F6,0) -> 0.16334609 | G13: =IFERROR((HistoricalsFS!G18-HistoricalsFS!G24)/HistoricalsFS!G6,0) -> 0.16729643 | H13: =IFERROR((HistoricalsFS!H18-HistoricalsFS!H24)/HistoricalsFS!H6,0) -> 0.18718599 | I13: =IFERROR((HistoricalsFS!I18-HistoricalsFS!I24)/HistoricalsFS!I6,0) -> 0.13701287 | J13: =IFERROR((HistoricalsFS!J18-HistoricalsFS!J24)/HistoricalsFS!J6,0) -> 0.15662629 | ... L13: =IFERROR((HistoricalsFS!L18-HistoricalsFS!L24)/HistoricalsFS!L6,0) -> 0.14687447 | N13: =AVERAGE(C13:L13) -> 0.16651831 | O13: =MEDIAN(C13:L13) -> 0.16815389
B14: Ebt Margin | C14: =IFERROR(HistoricalsFS!C28,0) -> 0.16819968 | D14: =IFERROR(HistoricalsFS!D28,0) -> 0.17405668 | E14: =IFERROR(HistoricalsFS!E28,0) -> 0.1665465 | F14: =IFERROR(HistoricalsFS!F28,0) -> 0.15760444 | G14: =IFERROR(HistoricalsFS!G28,0) -> 0.16223341 | H14: =IFERROR(HistoricalsFS!H28,0) -> 0.18296589 | I14: =IFERROR(HistoricalsFS!I28,0) -> 0.13373432 | J14: =IFERROR(HistoricalsFS!J28,0) -> 0.15243795 | ... L14: =IFERROR(HistoricalsFS!L28,0) -> 0.14017883 | N14: =AVERAGE(C14:L14) -> 0.16218388 | O14: =MEDIAN(C14:L14) -> 0.16438996
B15: Net Profit Margin | C15: =IFERROR(HistoricalsFS!C34,0) -> 0.13887197 | D15: =IFERROR(HistoricalsFS!D34,0) -> 0.14135051 | E15: =IFERROR(HistoricalsFS!E34,0) -> 0.14581549 | F15: =IFERROR(HistoricalsFS!F34,0) -> 0.13593983 | G15: =IFERROR(HistoricalsFS!G34,0) -> 0.1491031 | H15: =IFERROR(HistoricalsFS!H34,0) -> 0.16501656 | I15: =IFERROR(HistoricalsFS!I34,0) -> 0.12268945 | J15: =IFERROR(HistoricalsFS!J34,0) -> 0.14108173 | ... L15: =IFERROR(HistoricalsFS!L34,0) -> 0.12793395 | N15: =AVERAGE(C15:L15) -> 0.14411669 | O15: =MEDIAN(C15:L15) -> 0.14121612
B17: Sales Expense% Sales | C17: =IFERROR(HistoricalsFS!C16,0) -> 0.14943149 | D17: =IFERROR(HistoricalsFS!D16,0) -> 0.15506384 | E17: =IFERROR(HistoricalsFS!E16,0) -> 0.14421604 | F17: =IFERROR(HistoricalsFS!F16,0) -> 0.13354276 | G17: =IFERROR(HistoricalsFS!G16,0) -> 0.14306191 | H17: =IFERROR(HistoricalsFS!H16,0) -> 0.12997501 | I17: =IFERROR(HistoricalsFS!I16,0) -> 0.12738615 | J17: =IFERROR(HistoricalsFS!J16,0) -> 0.12937757 | ... L17: =IFERROR(HistoricalsFS!L16,0) -> 0.1521323 | N17: =AVERAGE(C17:L17) -> 0.1402229 | O17: =MEDIAN(C17:L17) -> 0.1405519
B18: Depriciation% Sales | C18: =IFERROR(HistoricalsFS!C25,0) -> 0.019309827 | D18: =IFERROR(HistoricalsFS!D25,0) -> 0.022227475 | E18: =IFERROR(HistoricalsFS!E25,0) -> 0.021425239 | F18: =IFERROR(HistoricalsFS!F25,0) -> 0.03233554 | G18: =IFERROR(HistoricalsFS!G25,0) -> 0.038617107 | H18: =IFERROR(HistoricalsFS!H25,0) -> 0.036442576 | I18: =IFERROR(HistoricalsFS!I25,0) -> 0.028052374 | J18: =IFERROR(HistoricalsFS!J25,0) -> 0.024878373 | ... L18: =IFERROR(HistoricalsFS!L25,0) -> 0.030270498 | N18: =AVERAGE(C18:L18) -> 0.027759074 | O18: =MEDIAN(C18:L18) -> 0.026465374
B19: Operating Income% Sales | C19: =C13 -> 0.1716331 | D19: =D13 -> 0.17653511 | E19: =E13 -> 0.16901136 | F19: =F13 -> 0.16334609 | G19: =G13 -> 0.16729643 | H19: =H13 -> 0.18718599 | I19: =I13 -> 0.13701287 | J19: =J13 -> 0.15662629 | ... L19: =L13 -> 0.14687447 | N19: =AVERAGE(C19:L19) -> 0.16651831 | O19: =MEDIAN(C19:L19) -> 0.16815389
B21: Return On Capital Employed | C21: =IFERROR((HistoricalsFS!C18-HistoricalsFS!C24)/SUM(HistoricalsFS!C48:C50),0) -> 0.35768409 | D21: =IFERROR((HistoricalsFS!D18-HistoricalsFS!D24)/SUM(HistoricalsFS!D48:D50),0) -> 0.32568534 | E21: =IFERROR((HistoricalsFS!E18-HistoricalsFS!E24)/SUM(HistoricalsFS!E48:E50),0) -> 0.31793919 | F21: =IFERROR((HistoricalsFS!F18-HistoricalsFS!F24)/SUM(HistoricalsFS!F48:F50),0) -> 0.29126565 | G21: =IFERROR((HistoricalsFS!G18-HistoricalsFS!G24)/SUM(HistoricalsFS!G48:G50),0) -> 0.30059314 | H21: =IFERROR((HistoricalsFS!H18-HistoricalsFS!H24)/SUM(HistoricalsFS!H48:H50),0) -> 0.29241025 | I21: =IFERROR((HistoricalsFS!I18-HistoricalsFS!I24)/SUM(HistoricalsFS!I48:I50),0) -> 0.25893857 | J21: =IFERROR((HistoricalsFS!J18-HistoricalsFS!J24)/SUM(HistoricalsFS!J48:J50),0) -> 0.30135929 | ... L21: =IFERROR((HistoricalsFS!L18-HistoricalsFS!L24)/SUM(HistoricalsFS!L48:L50),0) -> 0.22959184 | N21: =AVERAGE(C21:L21) -> 0.29929734 | O21: =MEDIAN(C21:L21) -> 0.30097621
B22: Retained Earnings% | C22: =IFERROR(HistoricalsFS!C44,0) -> 0 | D22: =IFERROR(HistoricalsFS!D44,0) -> 0 | E22: =IFERROR(HistoricalsFS!E44,0) -> 0 | F22: =IFERROR(HistoricalsFS!F44,0) -> 0 | G22: =IFERROR(HistoricalsFS!G44,0) -> 0 | H22: =IFERROR(HistoricalsFS!H44,0) -> 0 | I22: =IFERROR(HistoricalsFS!I44,0) -> 0 | J22: =IFERROR(HistoricalsFS!J44,0) -> 0 | ... L22: =IFERROR(HistoricalsFS!L44,0) -> 0 | N22: =AVERAGE(C22:L22) -> 0 | O22: =MEDIAN(C22:L22) -> 0
B23: Return on Equity% | C23: =IFERROR(HistoricalsFS!C33/SUM(HistoricalsFS!C48:C49),0) -> 0.30374938 | D23: =IFERROR(HistoricalsFS!D33/SUM(HistoricalsFS!D48:D49),0) -> 0.2799909 | E23: =IFERROR(HistoricalsFS!E33/SUM(HistoricalsFS!E48:E49),0) -> 0.29170189 | F23: =IFERROR(HistoricalsFS!F33/SUM(HistoricalsFS!F48:F49),0) -> 0.27617192 | G23: =IFERROR(HistoricalsFS!G33/SUM(HistoricalsFS!G48:G49),0) -> 0.29748395 | H23: =IFERROR(HistoricalsFS!H33/SUM(HistoricalsFS!H48:H49),0) -> 0.27978204 | I23: =IFERROR(HistoricalsFS!I33/SUM(HistoricalsFS!I48:I49),0) -> 0.25850954 | J23: =IFERROR(HistoricalsFS!J33/SUM(HistoricalsFS!J48:J49),0) -> 0.30425463 | ... L23: =IFERROR(HistoricalsFS!L33/SUM(HistoricalsFS!L48:L49),0) -> 0.22359394 | N23: =AVERAGE(C23:L23) -> 0.28438062 | O23: =MEDIAN(C23:L23) -> 0.2858464
B24: Self Sustained Growth Rate | C24: =C23*C22 -> 0 | D24: =D23*D22 -> 0 | E24: =E23*E22 -> 0 | F24: =F23*F22 -> 0 | G24: =G23*G22 -> 0 | H24: =H23*H22 -> 0 | I24: =I23*I22 -> 0 | J24: =J23*J22 -> 0 | ... L24: =L23*L22 -> 0 | N24: =AVERAGE(C24:L24) -> 0 | O24: =MEDIAN(C24:L24) -> 0
B25: Interest Coverage Ratio | C25: =IFERROR((HistoricalsFS!C18-HistoricalsFS!C240)/HistoricalsFS!C21,0) -> 55.613061 | D25: =IFERROR((HistoricalsFS!D18-HistoricalsFS!D240)/HistoricalsFS!D21,0) -> 80.19716 | E25: =IFERROR((HistoricalsFS!E18-HistoricalsFS!E240)/HistoricalsFS!E21,0) -> 77.260912 | F25: =IFERROR((HistoricalsFS!F18-HistoricalsFS!F240)/HistoricalsFS!F21,0) -> 34.081108 | G25: =IFERROR((HistoricalsFS!G18-HistoricalsFS!G240)/HistoricalsFS!G21,0) -> 40.670087 | H25: =IFERROR((HistoricalsFS!H18-HistoricalsFS!H240)/HistoricalsFS!H21,0) -> 52.991378 | I25: =IFERROR((HistoricalsFS!I18-HistoricalsFS!I240)/HistoricalsFS!I21,0) -> 50.347029 | J25: =IFERROR((HistoricalsFS!J18-HistoricalsFS!J240)/HistoricalsFS!J21,0) -> 43.335687 | ... L25: =IFERROR((HistoricalsFS!L18-HistoricalsFS!L240)/HistoricalsFS!L21,0) -> 26.456744 | N25: =AVERAGE(C25:L25) -> 49.792241 | O25: =MEDIAN(C25:L25) -> 46.841358
B27: Debt Turnover Ratio | C27: =IFERROR(HistoricalsFS!C6/HistoricalsFS!C60,0) -> 12.02478 | D27: =IFERROR(HistoricalsFS!D6/HistoricalsFS!D60,0) -> 10.411994 | E27: =IFERROR(HistoricalsFS!E6/HistoricalsFS!E60,0) -> 9.7216332 | F27: =IFERROR(HistoricalsFS!F6/HistoricalsFS!F60,0) -> 10.087468 | G27: =IFERROR(HistoricalsFS!G6/HistoricalsFS!G60,0) -> 11.258369 | H27: =IFERROR(HistoricalsFS!H6/HistoricalsFS!H60,0) -> 8.344109 | I27: =IFERROR(HistoricalsFS!I6/HistoricalsFS!I60,0) -> 7.5169136 | J27: =IFERROR(HistoricalsFS!J6/HistoricalsFS!J60,0) -> 7.4377909 | ... L27: =IFERROR(HistoricalsFS!L6/HistoricalsFS!L60,0) -> 7.8600767 | N27: =AVERAGE(C27:L27) -> 9.1923181 | O27: =MEDIAN(C27:L27) -> 9.0328711
B28: Credit Turnover Ratio | C28: =IFERROR(HistoricalsFS!C6/HistoricalsFS!C51,0) -> 3.8458091 | D28: =IFERROR(HistoricalsFS!D6/HistoricalsFS!D51,0) -> 3.551552 | E28: =IFERROR(HistoricalsFS!E6/HistoricalsFS!E51,0) -> 3.4907009 | F28: =IFERROR(HistoricalsFS!F6/HistoricalsFS!F51,0) -> 3.524679 | G28: =IFERROR(HistoricalsFS!G6/HistoricalsFS!G51,0) -> 4.1337633 | H28: =IFERROR(HistoricalsFS!H6/HistoricalsFS!H51,0) -> 3.3632319 | I28: =IFERROR(HistoricalsFS!I6/HistoricalsFS!I51,0) -> 3.8493808 | J28: =IFERROR(HistoricalsFS!J6/HistoricalsFS!J51,0) -> 4.390945 | ... L28: =IFERROR(HistoricalsFS!L6/HistoricalsFS!L51,0) -> 3.9128717 | N28: =AVERAGE(C28:L28) -> 3.8143684 | O28: =MEDIAN(C28:L28) -> 3.8475949
B29: Inventory Ratio | C29: =IFERROR(HistoricalsFS!C6/HistoricalsFS!C61,0) -> 7.14203 | D29: =IFERROR(HistoricalsFS!D6/HistoricalsFS!D61,0) -> 5.7336635 | E29: =IFERROR(HistoricalsFS!E6/HistoricalsFS!E61,0) -> 6.3290399 | F29: =IFERROR(HistoricalsFS!F6/HistoricalsFS!F61,0) -> 6.1082493 | G29: =IFERROR(HistoricalsFS!G6/HistoricalsFS!G61,0) -> 5.9623548 | H29: =IFERROR(HistoricalsFS!H6/HistoricalsFS!H61,0) -> 5.715998 | I29: =IFERROR(HistoricalsFS!I6/HistoricalsFS!I61,0) -> 4.7296237 | J29: =IFERROR(HistoricalsFS!J6/HistoricalsFS!J61,0) -> 5.5531459 | ... L29: =IFERROR(HistoricalsFS!L6/HistoricalsFS!L61,0) -> 5.0460273 | N29: =AVERAGE(C29:L29) -> 5.8312412 | O29: =MEDIAN(C29:L29) -> 5.8480092
B30: Fixed Asset Turnover | C30: =IFERROR(HistoricalsFS!C6/HistoricalsFS!C54,0) -> 4.1774086 | D30: =IFERROR(HistoricalsFS!D6/HistoricalsFS!D54,0) -> 4.5590724 | E30: =IFERROR(HistoricalsFS!E6/HistoricalsFS!E54,0) -> 4.5078961 | F30: =IFERROR(HistoricalsFS!F6/HistoricalsFS!F54,0) -> 2.9615874 | G30: =IFERROR(HistoricalsFS!G6/HistoricalsFS!G54,0) -> 3.2222977 | H30: =IFERROR(HistoricalsFS!H6/HistoricalsFS!H54,0) -> 3.7061903 | I30: =IFERROR(HistoricalsFS!I6/HistoricalsFS!I54,0) -> 5.2728689 | J30: =IFERROR(HistoricalsFS!J6/HistoricalsFS!J54,0) -> 5.9767488 | ... L30: =IFERROR(HistoricalsFS!L6/HistoricalsFS!L54,0) -> 3.6773592 | N30: =AVERAGE(C30:L30) -> 4.3028075 | O30: =MEDIAN(C30:L30) -> 4.3426524
B31: Capital Turnover Ratio | C31: =IFERROR(HistoricalsFS!C6/SUM(HistoricalsFS!C48:C49),0) -> 2.1872619 | D31: =IFERROR(HistoricalsFS!D6/SUM(HistoricalsFS!D48:D49),0) -> 1.9808269 | E31: =IFERROR(HistoricalsFS!E6/SUM(HistoricalsFS!E48:E49),0) -> 2.0004863 | F31: =IFERROR(HistoricalsFS!F6/SUM(HistoricalsFS!F48:F49),0) -> 2.0315747 | G31: =IFERROR(HistoricalsFS!G6/SUM(HistoricalsFS!G48:G49),0) -> 1.995156 | H31: =IFERROR(HistoricalsFS!H6/SUM(HistoricalsFS!H48:H49),0) -> 1.6954785 | I31: =IFERROR(HistoricalsFS!I6/SUM(HistoricalsFS!I48:I49),0) -> 2.1070234 | J31: =IFERROR(HistoricalsFS!J6/SUM(HistoricalsFS!J48:J49),0) -> 2.1565842 | ... L31: =IFERROR(HistoricalsFS!L6/SUM(HistoricalsFS!L48:L49),0) -> 1.7477295 | N31: =AVERAGE(C31:L31) -> 1.9797367 | O31: =MEDIAN(C31:L31) -> 1.9978212
B34: Debtor Days | C34: =365/C27 -> 30.353985 | D34: =365/D27 -> 35.055726 | E34: =365/E27 -> 37.545132 | F34: =365/F27 -> 36.183511 | G34: =365/G27 -> 32.420325 | H34: =365/H27 -> 43.743436 | I34: =365/I27 -> 48.557163 | J34: =365/J27 -> 49.073711 | ... L34: =365/L27 -> 46.437206 | N34: =AVERAGE(C34:L34) -> 40.964536 | O34: =MEDIAN(C34:L34) -> 40.644284
B35: Payable Days | C35: =365/C28 -> 94.908506 | D35: =365/D28 -> 102.77197 | E35: =365/E28 -> 104.56353 | F35: =365/F28 -> 103.55553 | G35: =365/G28 -> 88.297268 | H35: =365/H28 -> 108.52656 | I35: =365/I28 -> 94.820446 | J35: =365/J28 -> 83.125613 | ... L35: =365/L28 -> 93.281873 | N35: =AVERAGE(C35:L35) -> 96.329564 | O35: =MEDIAN(C35:L35) -> 94.864476
B36: Inventory Days | C36: =365/C29 -> 51.105918 | D36: =365/D29 -> 63.659125 | E36: =365/E29 -> 57.670675 | F36: =365/F29 -> 59.755256 | G36: =365/G29 -> 61.217423 | H36: =365/H29 -> 63.855866 | I36: =365/I29 -> 77.173159 | J36: =365/J29 -> 65.728509 | ... L36: =365/L29 -> 72.334131 | N36: =AVERAGE(C36:L36) -> 63.341177 | O36: =MEDIAN(C36:L36) -> 62.438274
B37: Cash Conversion Cycle | C37: =SUM(C34,C36)-C35 -> -13.448603 | D37: =SUM(D34,D36)-D35 -> -4.0571199 | E37: =SUM(E34,E36)-E35 -> -9.347721 | F37: =SUM(F34,F36)-F35 -> -7.6167625 | G37: =SUM(G34,G36)-G35 -> 5.3404812 | H37: =SUM(H34,H36)-H35 -> -0.92725992 | I37: =SUM(I34,I36)-I35 -> 30.909876 | J37: =SUM(J34,J36)-J35 -> 31.676607 | ... L37: =SUM(L34,L36)-L35 -> 25.489463 | N37: =AVERAGE(C37:L37) -> 7.9761485 | O37: =MEDIAN(C37:L37) -> 2.2066106
B39: CFO/Sales | C39: =IFERROR(HistoricalsFS!C71/HistoricalsFS!C6,0) -> 0.15716299 | D39: =IFERROR(HistoricalsFS!D71/HistoricalsFS!D6,0) -> 0.10140294 | E39: =IFERROR(HistoricalsFS!E71/HistoricalsFS!E6,0) -> 0.12561644 | F39: =IFERROR(HistoricalsFS!F71/HistoricalsFS!F6,0) -> 0.1283536 | G39: =IFERROR(HistoricalsFS!G71/HistoricalsFS!G6,0) -> 0.15031975 | H39: =IFERROR(HistoricalsFS!H71/HistoricalsFS!H6,0) -> 0.16963965 | I39: =IFERROR(HistoricalsFS!I71/HistoricalsFS!I6,0) -> 0.033898509 | J39: =IFERROR(HistoricalsFS!J71/HistoricalsFS!J6,0) -> 0.12158891 | ... L39: =IFERROR(HistoricalsFS!L71/HistoricalsFS!L6,0) -> 0.13047866 | N39: =AVERAGE(C39:L39) -> 0.12904194 | O39: =MEDIAN(C39:L39) -> 0.12941613
B40: CFO/Total Assets | C40: =IFERROR(HistoricalsFS!C71/HistoricalsFS!C65,0) -> 0.21242008 | D40: =IFERROR(HistoricalsFS!D71/HistoricalsFS!D65,0) -> 0.12312024 | E40: =IFERROR(HistoricalsFS!E71/HistoricalsFS!E65,0) -> 0.15355419 | F40: =IFERROR(HistoricalsFS!F71/HistoricalsFS!F65,0) -> 0.15198254 | G40: =IFERROR(HistoricalsFS!G71/HistoricalsFS!G65,0) -> 0.18826098 | H40: =IFERROR(HistoricalsFS!H71/HistoricalsFS!H65,0) -> 0.18095252 | I40: =IFERROR(HistoricalsFS!I71/HistoricalsFS!I65,0) -> 0.042968531 | J40: =IFERROR(HistoricalsFS!J71/HistoricalsFS!J65,0) -> 0.16266637 | ... L40: =IFERROR(HistoricalsFS!L71/HistoricalsFS!L65,0) -> 0.14573953 | N40: =AVERAGE(C40:L40) -> 0.15657935 | O40: =MEDIAN(C40:L40) -> 0.15811028
B41: CFO/Total Debt | C41: =IFERROR(HistoricalsFS!C71/HistoricalsFS!C50,0) -> 6.9378886 | D41: =IFERROR(HistoricalsFS!D71/HistoricalsFS!D50,0) -> 2.7257201 | E41: =IFERROR(HistoricalsFS!E71/HistoricalsFS!E50,0) -> 3.9619819 | F41: =IFERROR(HistoricalsFS!F71/HistoricalsFS!F50,0) -> 1.8714307 | G41: =IFERROR(HistoricalsFS!G71/HistoricalsFS!G50,0) -> 2.7162718 | H41: =IFERROR(HistoricalsFS!H71/HistoricalsFS!H50,0) -> 3.3695752 | I41: =IFERROR(HistoricalsFS!I71/HistoricalsFS!I50,0) -> 0.62165381 | J41: =IFERROR(HistoricalsFS!J71/HistoricalsFS!J50,0) -> 2.1698161 | ... L41: =IFERROR(HistoricalsFS!L71/HistoricalsFS!L50,0) -> 1.9316156 | N41: =AVERAGE(C41:L41) -> 2.8772673 | O41: =MEDIAN(C41:L41) -> 2.5914954

Sheet DCF>>>

Sheet DCF
B2: Calculation of PV of FCFF | E2: ='Intrinsic Growth'!K3 -> 45747 | F2: =E2+365 -> 46112 | G2: =F2+365 -> 46477 | H2: =G2+365 -> 46842 | I2: =H2+365 -> 47207 | J2: =I2+365 -> 47572
B4: EBIT | E4: =HistoricalsFS!C27+HistoricalsFS!C21 -> 2449.46 | F4: =E4*(1+$E$14) -> 2932.9483 | G4: =F4*(1+$E$14) -> 3511.8704 | H4: =G4*(1+$E$14) -> 4205.0633 | I4: =H4*(1+$E$14) -> 5035.0826 | J4: =I4*(1+$E$14) -> 6028.9358
B5: Tax Rate | E5: 0.25 | F5: 0.25 | G5: 0.25 | H5: 0.25 | I5: 0.25 | J5: 0.25
B6: EBIT(1-Tax) | E6: =E4*(1-E5) -> 1837.095 | F6: =F4*(1-F5) -> 2199.7113 | G6: =G4*(1-G5) -> 2633.9028 | H6: =H4*(1-H5) -> 3153.7975 | I6: =I4*(1-I5) -> 3776.3119 | J6: =J4*(1-J5) -> 4521.7018
B7: Less:Reinvestment Rate | E7: ='Intrinsic Growth'!K55 -> 0.55972692 | F7: =E7+(($J$7-$E$7)/4) -> 0.52467019 | G7: =F7+(($J$7-$E$7)/4) -> 0.48961346 | H7: =G7+(($J$7-$E$7)/4) -> 0.45455673 | I7: =H7+(($J$7-$E$7)/4) -> 0.4195 | J7: 0.4195
B8: Free Cash Flow to Firm (FCFF) | E8: =E6*(1-E7) -> 808.82348 | F8: =F6*(1-F7) -> 1045.5883 | G8: =G6*(1-G7) -> 1344.3085 | H8: =H6*(1-H7) -> 1720.2176 | I8: =I6*(1-I7) -> 2192.1491 | J8: =J6*(1-J7) -> 2624.8479
B9: Mid Year Convention | F9: 0.5 | G9: =F9+1 -> 1.5 | H9: =G9+1 -> 2.5 | I9: =H9+1 -> 3.5 | J9: =I9+1 -> 4.5
B10: Discounting Factor | F10: =1/(1+$E$16)^F9 -> 0.93696241 | G10: =1/(1+$E$16)^G9 -> 0.82255796 | H10: =1/(1+$E$16)^H9 -> 0.72212245 | I10: =1/(1+$E$16)^I9 -> 0.63395027 | J10: =1/(1+$E$16)^J9 -> 0.55654403
B12: PV of FCFF | F12: =F8*F10 -> 979.67697 | G12: =G8*G10 -> 1105.7717 | H12: =H8*H10 -> 1242.2078 | I12: =I8*I10 -> 1389.7135 | J12: =J8*J10 -> 1460.8434
B14: Expected Growth | E14: ='Intrinsic Growth'!K65 -> 0.19738568
B15: terminal Growth | E15: 0.076
B16: WACC | E16: =WACC!J39 -> 0.13908376
B19: Calculation of Terminal Value
B21: FCFF(n-1) | D21: =J8*(1+E14) -> 3142.9553
B22: WACC | D22: =E16 -> 0.13908376
B23: Terminal Growth Rate | D23: =E15 -> 0.076
B25: Terminal Value | D25: =D21/(D22-D23) -> 49821.939
B28: Calculation of Equity Value per Share
B30: Pv of FCFF | D30: =SUM(F12:J12) -> 6178.2133
B31: Pv of Terminal Value | D31: =D25*J10 -> 27728.103
B32: Value of Operating Aseets | D32: =SUM(D30:D31) -> 33906.316
B34: Add: Cash | D34: ='Data Sheet'!K69 -> 781.98
B35: Less: Debt | D35: =SUM('Raw FS'!N7,'Raw FS'!N8) -> 864
B36: Value of Equity | D36: =D32+D34-D35 -> 33824.296
B37: No. of Shares | D37: ='Data Sheet'!B6 -> 95.929135
B39: Equity Value per Share | D39: =D36/D37 -> 352.5967
B41: Share Price | D41: 2514
B42: Discount/Premium | D42: =D41/D39 -> 7.129959

Sheet WACC
A2: # | B2: Peer Comps
G3: Debt / | H3: Debt / | I3: Levered | J3: Unlevered
A4: # | B4: Name of Company | C4: Country | D4: Total Debt | E4: Total Equity | F4: Tax Rate1 | G4: Equity | H4: Capital | I4: Beta2 | J4: Beta3
B6: Asian Paints | C6: India | D6: 3557.09 | E6: 237575.97 | F6: 0.3 | G6: =D6/E6 -> 0.014972432 | H6: =D6/(E6+D6) -> 0.014751565 | I6: 0.865 | J6: =I6/(1+(1-F6)*G6) -> 0.85602822
B7: Berger Paints | C7: India | D7: 697.33 | E7: 54364.73 | F7: 0.3 | G7: =D7/E7 -> 0.012826882 | H7: =D7/(E7+D7) -> 0.012664437 | I7: 0.922 | J7: =I7/(1+(1-F7)*G7) -> 0.9137952
B8: Kansal Nerolac | C8: India | D8: 276.42 | E8: 15940.89 | F8: 0.3 | G8: =D8/E8 -> 0.017340312 | H8: =D8/(E8+D8) -> 0.01704475 | I8: 0.847 | J8: =I8/(1+(1-F8)*G8) -> 0.83684223
B9: JSW Dulux | C9: India | D9: 71.2 | E9: 13446.66 | F9: 0.3 | G9: =D9/E9 -> 0.0052949952 | H9: =D9/(E9+D9) -> 0.0052671059 | I9: 0.416 | J9: =I9/(1+(1-F9)*G9) -> 0.41446379
B10: Indigo Paints | C10: India | D10: 17.64 | E10: 4107.39 | F10: 0.3 | G10: =D10/E10 -> 0.0042946981 | H10: =D10/(E10+D10) -> 0.0042763325 | I10: 1.07 | J10: =I10/(1+(1-F10)*G10) -> 1.0667929
E12: Average | F12: =AVERAGE(F6:F10) -> 0.3 | G12: =AVERAGE(G6:G10) -> 0.010945864 | H12: =AVERAGE(H6:H10) -> 0.010800838 | I12: =AVERAGE(I6:I10) -> 0.824 | J12: =AVERAGE(J6:J10) -> 0.81758447
E13: Median | F13: =MEDIAN(F6:F10) -> 0.3 | G13: =MEDIAN(G6:G10) -> 0.012826882 | H13: =MEDIAN(H6:H10) -> 0.012664437 | I13: =MEDIAN(I6:I10) -> 0.865 | J13: =MEDIAN(J6:J10) -> 0.85602822
B16: Cost of Debt | G16: Cost of Equity
B18: Pre-Tax Cost of Debt | E18: =227/3557 -> 0.063817824 | G18: Risk Free Rate | J18: 0.06933
B19: Tax Rate | E19: =F12 -> 0.3 | G19: Equity Risk Premium | J19: =RM!H7-WACC!J18 -> 0.082162308
B20: Post Tax Cost of Debt | E20: =E18*(1-E19) -> 0.044672477 | G20: Levered Beta4 | J20: =J29 -> 0.86371434
G21: Cost of Equity | J21: =J18+(J19*J20) -> 0.14029476
B24: Capital Structure | G24: Levered Beta
D26: Current | E26: Target | G26: Comps Median Unlevered Beta | J26: =J13 -> 0.85602822
B27: Total Debt | C27: =D6 -> 3557.09 | D27: =C27/C29 -> 0.014751565 | E27: =H13 -> 0.012664437 | G27: Target Debt/Equity | J27: =E31 -> 0.012826882
B28: Market Capitalization | C28: =E6 -> 237575.97 | D28: =C28/C29 -> 0.98524844 | E28: =E29-E27 -> 0.98733556 | G28: Tax Rate | J28: =F13 -> 0.3
B29: Total Capital | C29: =SUM(C27:C28) -> 241133.06 | D29: =SUM(D27:D28) -> 1 | E29: 1 | G29: Levered Beta | J29: =J26*(1+(1-J28)*J27) -> 0.86371434
B31: Debt/Equity | D31: =D27/D28 -> 0.014972432 | E31: =E27/E28 -> 0.012826882 | G31: WACC
G33: Cost of Equity | J33: =J21 -> 0.14029476
G34: Equity Weight | J34: =E28 -> 0.98733556
G36: Cost of Debt | J36: =E20 -> 0.044672477
G37: Debt Weight | J37: =E27 -> 0.012664437
G39: WACC | J39: =(J33*J34)+(J36*J37) -> 0.13908376

Sheet Intrinsic Growth
B3: Calculation of ROIC | G3: =IFERROR('Data Sheet'!$G$16,0) -> 44286 | H3: =IFERROR('Data Sheet'!$H$16,0) -> 44651 | I3: =IFERROR('Data Sheet'!$I$16,0) -> 45016 | J3: =IFERROR('Data Sheet'!$J$16,0) -> 45382 | K3: =IFERROR('Data Sheet'!$K$16,0) -> 45747
B5: Current Assets
B6: =IFERROR('Raw FS'!B35,0) -> Inventories | G6: ='Raw FS'!J35 -> 3799 | H6: ='Raw FS'!K35 -> 6153 | I6: ='Raw FS'!L35 -> 6211 | J6: ='Raw FS'!M35 -> 5923 | K6: ='Raw FS'!N35 -> 6719
B7: =IFERROR('Raw FS'!B36,0) -> Trade receivables + | G7: ='Raw FS'!J36 -> 2602 | H7: ='Raw FS'!K36 -> 3871 | I7: ='Raw FS'!L36 -> 4637 | J7: ='Raw FS'!M36 -> 4889 | K7: ='Raw FS'!N36 -> 4314
B8: =IFERROR('Raw FS'!B37,0) -> Cash Equivalents | G8: ='Raw FS'!J38 -> 12 | H8: ='Raw FS'!K38 -> 8 | I8: ='Raw FS'!L38 -> 12 | J8: ='Raw FS'!M38 -> 17 | K8: ='Raw FS'!N38 -> 22
B9: =IFERROR('Raw FS'!B38,0) -> Loans n Advances | G9: ='Raw FS'!J39 -> 2554 | H9: ='Raw FS'!K39 -> 2869 | I9: ='Raw FS'!L39 -> 3024 | J9: ='Raw FS'!M39 -> 3555 | K9: ='Raw FS'!N39 -> 3319
B10: Total Current Assets | G10: =SUM(G6:G9) -> 8967 | H10: =SUM(H6:H9) -> 12901 | I10: =SUM(I6:I9) -> 13884 | J10: =SUM(J6:J9) -> 14384 | K10: =SUM(K6:K9) -> 14374
B12: Current Liabilities
B13: ='Raw FS'!B13 -> Trade Payables | G13: ='Raw FS'!C13 -> 1746 | H13: ='Raw FS'!D13 -> 1549 | I13: ='Raw FS'!E13 -> 1565 | J13: ='Raw FS'!F13 -> 1923 | K13: ='Raw FS'!G13 -> 2160
B14: ='Raw FS'!B14 -> Advance from Customers | G14: ='Raw FS'!C14 -> 0 | H14: ='Raw FS'!D14 -> 5 | I14: ='Raw FS'!E14 -> 12 | J14: ='Raw FS'!F14 -> 17 | K14: ='Raw FS'!G14 -> 16
B15: ='Raw FS'!B15 -> Other liability items | G15: ='Raw FS'!C15 -> 1795 | H15: ='Raw FS'!D15 -> 1937 | I15: ='Raw FS'!E15 -> 1750 | J15: ='Raw FS'!F15 -> 1925 | K15: ='Raw FS'!G15 -> 2316
B16: Total Current Liabilities | G16: =SUM(G13:G15) -> 3541 | H16: =SUM(H13:H15) -> 3491 | I16: =SUM(I13:I15) -> 3327 | J16: =SUM(J13:J15) -> 3865 | K16: =SUM(K13:K15) -> 4492
A18: # | B18: Net Working Capital | G18: =G10-G16 -> 5426 | H18: =H10-H16 -> 9410 | I18: =I10-I16 -> 10557 | J18: =J10-J16 -> 10519 | K18: =K10-K16 -> 9882
B20: Non Current Assets
B21: ='Raw FS'!B19 -> Land | G21: ='Raw FS'!J19 -> 644 | H21: ='Raw FS'!K19 -> 644 | I21: ='Raw FS'!L19 -> 804 | J21: ='Raw FS'!M19 -> 1126 | K21: ='Raw FS'!N19 -> 1050
B22: ='Raw FS'!B20 -> Building | G22: ='Raw FS'!J20 -> 2249 | H22: ='Raw FS'!K20 -> 2325 | I22: ='Raw FS'!L20 -> 2883 | J22: ='Raw FS'!M20 -> 3390 | K22: ='Raw FS'!N20 -> 4136
B23: ='Raw FS'!B21 -> Plant Machinery | G23: ='Raw FS'!J21 -> 4340 | H23: ='Raw FS'!K21 -> 4531 | I23: ='Raw FS'!L21 -> 4825 | J23: ='Raw FS'!M21 -> 5422 | K23: ='Raw FS'!N21 -> 7576
B24: ='Raw FS'!B22 -> Equipments | G24: ='Raw FS'!J22 -> 243 | H24: ='Raw FS'!K22 -> 253 | I24: ='Raw FS'!L22 -> 270 | J24: ='Raw FS'!M22 -> 298 | K24: ='Raw FS'!N22 -> 325
B25: ='Raw FS'!B23 -> Furniture n fittings | G25: ='Raw FS'!J23 -> 99 | H25: ='Raw FS'!K23 -> 113 | I25: ='Raw FS'!L23 -> 146 | J25: ='Raw FS'!M23 -> 175 | K25: ='Raw FS'!N23 -> 203
B26: ='Raw FS'!B24 -> Vehicles | G26: ='Raw FS'!J24 -> 38 | H26: ='Raw FS'!K24 -> 32 | I26: ='Raw FS'!L24 -> 36 | J26: ='Raw FS'!M24 -> 40 | K26: ='Raw FS'!N24 -> 39
B27: ='Raw FS'!B25 -> Intangible Assets | G27: ='Raw FS'!J25 -> 476 | H27: ='Raw FS'!K25 -> 345 | I27: ='Raw FS'!L25 -> 422 | J27: ='Raw FS'!M25 -> 850 | K27: ='Raw FS'!N25 -> 827
B28: ='Raw FS'!B26 -> Other fixed assets | G28: ='Raw FS'!J26 -> 302 | H28: ='Raw FS'!K26 -> 294 | I28: ='Raw FS'!L26 -> 289 | J28: ='Raw FS'!M26 -> 321 | K28: ='Raw FS'!N26 -> 328
B30: ='Raw FS'!B27 -> Gross Block | G30: =SUM(G21:G29) -> 8391 | H30: =SUM(H21:H29) -> 8537 | I30: =SUM(I21:I29) -> 9675 | J30: =SUM(J21:J29) -> 11622 | K30: =SUM(K21:K29) -> 14484
B31: ='Raw FS'!B28 -> Accumulated Depreciation | G31: =-('Raw FS'!J28) -> -2533 | H31: =-('Raw FS'!K28) -> -3019 | I31: =-('Raw FS'!L28) -> -3905 | J31: =-('Raw FS'!M28) -> -4475 | K31: =-('Raw FS'!N28) -> -5264
A33: # | B33: Net Non Current Assets | G33: =SUM(G30:G31) -> 5858 | H33: =SUM(H30:H31) -> 5518 | I33: =SUM(I30:I31) -> 5770 | J33: =SUM(J30:J31) -> 7147 | K33: =SUM(K30:K31) -> 9220
A35: # | B35: Invested Capital | G35: =G33+G18 -> 11284 | H35: =H33+H18 -> 14928 | I35: =I33+I18 -> 16327 | J35: =J33+J18 -> 17666 | K35: =K33+K18 -> 19102
B36: EBIT | G36: =IFERROR(HistoricalsFS!H27+HistoricalsFS!H21,0) -> 4064.33 | H36: =IFERROR(HistoricalsFS!I27+HistoricalsFS!I21,0) -> 3987.25 | I36: =IFERROR(HistoricalsFS!J27+HistoricalsFS!J21,0) -> 5401.82 | J36: =IFERROR(HistoricalsFS!K27+HistoricalsFS!K21,0) -> 6731.98 | K36: =IFERROR(HistoricalsFS!L27+HistoricalsFS!L21,0) -> 4979.87
B38: ROIC | G38: =G36/G35 -> 0.36018522 | H38: =H36/H35 -> 0.26709874 | I38: =I36/I35 -> 0.33085196 | J38: =J36/J35 -> 0.38106985 | K38: =K36/K35 -> 0.26069888
A41: # | B41: Calculation of Reinvestment Rate | G41: =IFERROR('Data Sheet'!$G$16,0) -> 44286 | H41: =IFERROR('Data Sheet'!$H$16,0) -> 44651 | I41: =IFERROR('Data Sheet'!$I$16,0) -> 45016 | J41: =IFERROR('Data Sheet'!$J$16,0) -> 45382 | K41: =IFERROR('Data Sheet'!$K$16,0) -> 45747
B43: Net Capex | G43: =IFERROR(-SUM('Raw FS'!J53:J54),0) -> 261 | H43: =IFERROR(-SUM('Raw FS'!K53:K54),0) -> 511 | I43: =IFERROR(-SUM('Raw FS'!L53:L54),0) -> 1420 | J43: =IFERROR(-SUM('Raw FS'!M53:M54),0) -> 2491 | K43: =IFERROR(-SUM('Raw FS'!N53:N54),0) -> 1820
B44: Change in Working Capital | H44: =H18-G18 -> 3984 | I44: =I18-H18 -> 1147 | J44: =J18-I18 -> -38 | K44: =K18-J18 -> -637
B46: EBIT | G46: =G36 -> 4064.33 | H46: =H36 -> 3987.25 | I46: =I36 -> 5401.82 | J46: =J36 -> 6731.98 | K46: =K36 -> 4979.87
B47: Marginal Tax Rate | G47: 0.25 | H47: 0.25 | I47: 0.25 | J47: 0.25 | K47: 0.25
B48: EBIT(1-T) | G48: =G46*(1-G47) -> 3048.2475 | H48: =H46*(1-H47) -> 2990.4375 | I48: =I46*(1-I47) -> 4051.365 | J48: =J46*(1-J47) -> 5048.985 | K48: =K46*(1-K47) -> 3734.9025
B50: Reinvestment | H50: =H43+H44 -> 4495 | I50: =I43+I44 -> 2567 | J50: =J43+J44 -> 2453 | K50: =K43+K44 -> 1183
B52: Reinvestment Rate | H52: =H50/H48 -> 1.5031245 | I52: =I50/I48 -> 0.63361361 | J52: =J50/J48 -> 0.48584022 | K52: =K50/K48 -> 0.31674187
J54: 4 Year Average | K54: =AVERAGE(H52:K52) -> 0.73483006
J55: 4 Year Median | K55: =MEDIAN(H52:K52) -> 0.55972692
A57: # | B57: Calculation of Growth Rate | G57: =IFERROR('Data Sheet'!$G$16,0) -> 44286 | H57: =IFERROR('Data Sheet'!$H$16,0) -> 44651 | I57: =IFERROR('Data Sheet'!$I$16,0) -> 45016 | J57: =IFERROR('Data Sheet'!$J$16,0) -> 45382 | K57: =IFERROR('Data Sheet'!$K$16,0) -> 45747
B59: Reinvestment Rate | H59: =H52 -> 1.5031245 | I59: =I52 -> 0.63361361 | J59: =J52 -> 0.48584022 | K59: =K52 -> 0.31674187
...

Sheet RM
C2: Nifty 50 past years return
C3: Year | D3: Annual
C4: 2000 | D4: -0.1465
C5: 2001 | D5: -0.1618 | F5: Average Return | H5: =AVERAGE(D4:D29) -> 0.15149231
C6: 2002 | D6: 0.0325 | F6: Dividend Yield | H6: 1.28%1
C7: 2003 | D7: 0.719 | F7: Total Market Return | H7: =SUM(H5:H6) -> 0.15149231
C8: 2004 | D8: 0.1068
C9: 2005 | D9: 0.3634
C10: 2006 | D10: 0.3983
C11: 2007 | D11: 0.5477
C12: 2008 | D12: -0.5179
C13: 2009 | D13: 0.7576
C14: 2010 | D14: 0.1795
C15: 2011 | D15: -0.2462
C16: 2012 | D16: 0.277
C17: 2013 | D17: 0.0676
C18: 2014 | D18: 0.3139
C19: 2015 | D19: -0.0406
... C29: 2025 | D29: 0.1051

Sheet Data Room>>>

Sheet Data Sheet
A1: COMPANY NAME | B1: ASIAN PAINTS LTD | E1: =IF(B2<>B3, "A NEW VERSION OF THE WORKSHEET IS AVAILABLE", "")
A2: LATEST VERSION | B2: 2.1 | E2: PLEASE DO NOT MAKE ANY CHANGES TO THIS SHEET
A3: CURRENT VERSION | B3: 2.1
A5: META
A6: Number of shares | B6: =IF(B9>0, B9/B8, 0) -> 95.929135
A7: Face Value | B7: 1
A8: Current Price | B8: 2514.5
A9: Market Capitalization | B9: 241213.81
A15: PROFIT & LOSS
A16: Report Date | B16: 42460 | C16: 42825 | D16: 43190 | E16: 43555 | F16: 43921 | G16: 44286 | H16: 44651 | I16: 45016 | J16: 45382 | K16: 45747
A17: Sales | B17: 14271.49 | C17: 15061.99 | D17: 16824.55 | E17: 19240.13 | F17: 20211.25 | G17: 21712.79 | H17: 29101.28 | I17: 34488.59 | J17: 35494.73 | K17: 33905.62
A18: Raw Material Cost | B18: 6569.83 | C18: 7452.6 | D18: 8128.17 | E18: 9974.4 | F18: 9981.99 | G18: 10425.55 | H18: 17123.25 | I18: 18985.53 | J18: 17410.84 | K18: 17504.51
A19: Change in Inventory | B19: -199.33 | C19: 528.6 | D19: -142.13 | E19: 293.26 | F19: 239.15 | G19: 92.45 | H19: 1324.97 | I19: 309.73 | J19: -363.8 | K19: 205
A20: Power and Fuel | B20: 114.48 | C20: 106.02 | D20: 110.3 | E20: 119.63 | F20: 97.79 | G20: 86.05 | H20: 117.23 | I20: 138.29 | J20: 133.25 | K20: 148.58
A21: Other Mfr. Exp | B21: 1535.22 | C21: 1662.75 | D21: 1691.68 | E21: 1862.35 | F21: 1946.12 | G21: 2068.31 | H21: 2880.45 | I21: 2916.2 | J21: 2767.18 | K21: 2687.4
A22: Employee Cost | B22: 994.98 | C22: 1039.89 | D22: 1121.89 | E22: 1242.69 | F22: 1371.27 | G22: 1547.61 | H22: 1794.61 | I22: 2036.41 | J22: 2334.92 | K22: 2605.78
A23: Selling and admin | B23: 3912.3 | C23: 4364.04 | D23: 2254.92 | E23: 2366.87 | F23: 2311.51 | G23: 2245.69 | H23: 2941.98 | I23: 3500.84 | J23: 3811.86 | K23: 3874.94
A24: Other Expenses | B24: -1779.69 | C24: -2028.47 | D24: 171.45 | E24: 202.51 | F24: 579.95 | G24: 576.43 | H24: 765.12 | I24: 961.21 | J24: 1087.9 | K24: 1283.2
A25: Other Income | B25: 213.39 | C25: 337.9 | D25: 336.41 | E25: 273.77 | F25: 350.1 | G25: 331.65 | H25: 295.88 | I25: 431.46 | J25: 820.96 | K25: 350.22
A26: Depreciation | B26: 275.58 | C26: 334.79 | D26: 360.47 | E26: 622.14 | F26: 780.5 | G26: 791.27 | H26: 816.36 | I26: 858.02 | J26: 853 | K26: 1026.34
A27: Interest | B27: 49 | C27: 37.33 | D27: 41.47 | E27: 110.47 | F27: 102.33 | G27: 91.63 | H27: 95.41 | I27: 144.45 | J27: 205.17 | K27: 227.02
... A31: Dividend Amount | B31: 719.4 | C31: 987.98 | D31: 834.5 | E31: 1007.16 | F31: 1151.04 | G31: 1712.17 | H31: 1836.87 | I31: 2460.35 | J31: 3194.14 | K31: 2378.82
A40: Quarters
A41: Report Date | B41: 45199 | C41: 45291 | D41: 45382 | E41: 45473 | F41: 45565 | G41: 45657 | H41: 45747 | I41: 45838 | J41: 45930 | K41: 46022
A42: Sales | B42: 8478.57 | C42: 9103.09 | D42: 8730.76 | E42: 8969.73 | F42: 8027.54 | G42: 8549.44 | H42: 8358.91 | I42: 8938.55 | J42: 8531.27 | K42: 8867.02
A43: Expenses | B43: 6762.34 | C43: 7047 | D43: 7039.39 | E43: 7275.96 | F43: 6788.03 | G43: 6912.71 | H43: 6922.71 | I43: 7313.58 | J43: 7027.89 | K43: 7086.06
A44: Other Income | B44: 194.33 | C44: 186.46 | D44: 212.43 | E44: 192.93 | F44: 24.53 | G44: 192.82 | H44: -60.06 | I44: 229.11 | J44: 236.94 | K44: 69.14
A45: Depreciation | B45: 208.72 | C45: 220.35 | D45: 225.61 | E45: 227.7 | F45: 241.99 | G45: 255.55 | H45: 301.1 | I45: 300.87 | J45: 304.93 | K45: 313.07
A46: Interest | B46: 50.9 | C46: 54.42 | D46: 54.1 | E46: 55.38 | F46: 63.01 | G46: 55.84 | H46: 52.79 | I46: 44.5 | J46: 43.87 | K46: 47.94
A47: Profit before tax | B47: 1650.94 | C47: 1967.78 | D47: 1624.09 | E47: 1603.62 | F47: 959.04 | G47: 1518.16 | H47: 1022.25 | I47: 1508.71 | J47: 1391.52 | K47: 1489.09
A48: Tax | B48: 418.55 | C48: 492.62 | D48: 348.79 | E48: 416.83 | F48: 265.38 | G48: 389.73 | H48: 321.42 | I48: 391.66 | J48: 373.29 | K48: 415.17
A49: Net profit | B49: 1205.42 | C49: 1447.72 | D49: 1256.72 | E49: 1169.98 | F49: 694.64 | G49: 1110.48 | H49: 692.13 | I49: 1099.77 | J49: 993.59 | K49: 1059.87
A50: Operating Profit | B50: 1716.23 | C50: 2056.09 | D50: 1691.37 | E50: 1693.77 | F50: 1239.51 | G50: 1636.73 | H50: 1436.2 | I50: 1624.97 | J50: 1503.38 | K50: 1780.96
A55: BALANCE SHEET
A56: Report Date | B56: 42460 | C56: 42825 | D56: 43190 | E56: 43555 | F56: 43921 | G56: 44286 | H56: 44651 | I56: 45016 | J56: 45382 | K56: 45747
A57: Equity Share Capital | B57: 95.92 | C57: 95.92 | D57: 95.92 | E57: 95.92 | F57: 95.92 | G57: 95.92 | H57: 95.92 | I57: 95.92 | J57: 95.92 | K57: 95.92
A58: Reserves | B58: 6428.9 | C58: 7507.97 | D58: 8314.31 | E58: 9374.63 | F58: 10034.24 | G58: 12710.37 | H58: 13715.64 | I58: 15896.31 | J58: 18632.38 | K58: 19303.89
A59: Borrowings | B59: 323.29 | C59: 560.34 | D59: 533.43 | E59: 1319.6 | F59: 1118.5 | G59: 1093.12 | H59: 1586.88 | I59: 1932.62 | J59: 2474.38 | K59: 2290.29
A60: Other Liabilities | B60: 3710.92 | C60: 4240.96 | D60: 4819.82 | E60: 5458.69 | F60: 4889.31 | G60: 6455.93 | H60: 7559.99 | I60: 7854.48 | J60: 8698.09 | K60: 8665.15
A61: Total | B61: 10559.03 | C61: 12405.19 | D61: 13763.48 | E61: 16248.84 | F61: 16137.97 | G61: 20355.34 | H61: 22958.43 | I61: 25779.33 | J61: 29900.77 | K61: 30355.25
...

Sheet Raw FS
B2: Particulars | C2: 41699 | D2: 42064 | E2: 42430 | F2: 42795 | G2: 43160 | H2: 43525 | I2: 43891 | J2: 44256 | K2: 44621 | L2: 44986 | M2: 45352 | N2: 45717
C3: 41699 | D3: 42064 | E3: 42430 | F3: 42795 | G3: 43160 | H3: 43525 | I3: 43891 | J3: 44256 | K3: 44621 | L3: 44986 | M3: 45352 | N3: 45717
B4: Equity Capital | C4: 96 | D4: 96 | E4: 96 | F4: 96 | G4: 96 | H4: 96 | I4: 96 | J4: 96 | K4: 96 | L4: 96 | M4: 96 | N4: 96
B5: Reserves | C5: 3943 | D5: 4646 | E5: 6429 | F5: 7508 | G5: 8314 | H5: 9375 | I5: 10034 | J5: 12710 | K5: 13716 | L5: 15896 | M5: 18632 | N5: 19304
B6: Borrowings - | C6: 249 | D6: 418 | E6: 323 | F6: 560 | G6: 533 | H6: 1320 | I6: 1118 | J6: 1093 | K6: 1587 | L6: 1933 | M6: 2474 | N6: 2290
B7: Long term Borrowings | C7: 41 | D7: 78 | E7: 73 | F7: 41 | G7: 28 | H7: 19 | I7: 19 | J7: 15 | K7: 45 | L7: 76 | M7: 54 | N7: 260
B8: Short term Borrowings | C8: 199 | D8: 332 | E8: 231 | F8: 504 | G8: 492 | H8: 597 | I8: 321 | J8: 326 | K8: 731 | L8: 896 | M8: 1053 | N8: 604
B9: Lease Liabilities | C9: 0 | D9: 0 | E9: 0 | F9: 0 | G9: 0 | H9: 693 | I9: 764 | J9: 745 | K9: 811 | L9: 960 | M9: 1367 | N9: 1427
B10: Other Borrowings | C10: 9 | D10: 8 | E10: 20 | F10: 15 | G10: 13 | H10: 11 | I10: 15 | J10: 8 | K10: 0 | L10: 0 | M10: 0 | N10: 0
B11: Other Liabilities - | C11: 3787 | D11: 3754 | E11: 3711 | F11: 4241 | G11: 4820 | H11: 5459 | I11: 4889 | J11: 6456 | K11: 7560 | L11: 7854 | M11: 8698 | N11: 8665
B12: Non controlling int | C12: 246 | D12: 264 | E12: 384 | F12: 375 | G12: 328 | H12: 361 | I12: 404 | J12: 423 | K12: 388 | L12: 454 | M12: 695 | N12: 659
B13: Trade Payables | C13: 1746 | D13: 1549 | E13: 1565 | F13: 1923 | G13: 2160 | H13: 2394 | I13: 2137 | J13: 3379 | K13: 4164 | L13: 3635 | M13: 3831 | N13: 3848
B14: Advance from Customers | C14: 0 | D14: 5 | E14: 12 | F14: 17 | G14: 16 | H14: 13 | I14: 29 | J14: 41 | K14: 76 | L14: 108 | M14: 154 | N14: 173
B15: Other liability items | C15: 1795 | D15: 1937 | E15: 1750 | F15: 1925 | G15: 2316 | H15: 2690 | I15: 2320 | J15: 2613 | K15: 2932 | L15: 3657 | M15: 4017 | N15: 3985
B16: Total Liabilities | C16: 8075 | D16: 8914 | E16: 10559 | F16: 12405 | G16: 13763 | H16: 16249 | I16: 16138 | J16: 20355 | K16: 22958 | L16: 25779 | M16: 29901 | N16: 30355
B18: Fixed Assets -
B19: Land | C19: 247 | D19: 251 | E19: 429 | F19: 408 | G19: 586 | H19: 605 | I19: 640 | J19: 644 | K19: 644 | L19: 804 | M19: 1126 | N19: 1050
B20: Building | C20: 931 | D20: 962 | E20: 923 | F20: 931 | G20: 957 | H20: 2402 | I20: 2257 | J20: 2249 | K20: 2325 | L20: 2883 | M20: 3390 | N20: 4136
B21: Plant Machinery | C21: 2054 | D21: 2132 | E21: 1793 | F21: 1980 | G21: 2157 | H21: 4006 | I21: 4208 | J21: 4340 | K21: 4531 | L21: 4825 | M21: 5422 | N21: 7576
B22: Equipments | C22: 155 | D22: 171 | E22: 97 | F22: 119 | G22: 200 | H22: 221 | I22: 241 | J22: 243 | K22: 253 | L22: 270 | M22: 298 | N22: 325
B23: Furniture n fittings | C23: 71 | D23: 83 | E23: 49 | F23: 59 | G23: 72 | H23: 88 | I23: 94 | J23: 99 | K23: 113 | L23: 146 | M23: 175 | N23: 203
B24: Vehicles | C24: 14 | D24: 18 | E24: 11 | F24: 14 | G24: 27 | H24: 47 | I24: 43 | J24: 38 | K24: 32 | L24: 36 | M24: 40 | N24: 39
B25: Intangible Assets | C25: 203 | D25: 351 | E25: 339 | F25: 276 | G25: 468 | H25: 512 | I25: 505 | J25: 476 | K25: 345 | L25: 422 | M25: 850 | N25: 827
B26: Other fixed assets | C26: 128 | D26: 145 | E26: 103 | F26: 128 | G26: 238 | H26: 261 | I26: 293 | J26: 302 | K26: 294 | L26: 289 | M26: 321 | N26: 328
B27: Gross Block | C27: 3804 | D27: 4112 | E27: 3744 | F27: 3914 | G27: 4705 | H27: 8141 | I27: 8282 | J27: 8392 | K27: 8538 | L27: 9676 | M27: 11622 | N27: 14484
B28: Accumulated Depreciation | C28: 1242 | D28: 1452 | E28: 327 | F28: 610 | G28: 973 | H28: 1644 | I28: 2010 | J28: 2533 | K28: 3019 | L28: 3905 | M28: 4475 | N28: 5264
B29: Net Block | C29: =C27-C28 -> 2562 | D29: =D27-D28 -> 2660 | E29: =E27-E28 -> 3417 | F29: =F27-F28 -> 3304 | G29: =G27-G28 -> 3732 | H29: =H27-H28 -> 6497 | I29: =I27-I28 -> 6272 | J29: =J27-J28 -> 5859 | ... N29: =N27-N28 -> 9220
